Workbook

Sheet 📋 Index
B1: PORTFOLIO MASTER FILE — HU3110
B2: HU3110 · Zerodha Demat · Update prices: 📥 Price Hub col H → all sheets recalculate
B5: TOTAL INVESTED | D5: MARKET VALUE | F5: RETURN | G5: UNREALISED P&L
B6: {='📊 Portfolio Brief'!G40} -> 8790005.6 | D6: {='📊 Portfolio Brief'!H40} -> 10119824 | F6: 15.1% | G6: {='📊 Portfolio Brief'!I40/'📊 Portfolio Brief'!G40} -> 0.15128753
G7: {='📊 Portfolio Brief'!I40} -> 1329818.3
B10: HU3110 · PORTFOLIO MASTER FILE · Zerodha Demat · 6 March 2026
B11: ₹87.9L invested · ₹1.01Cr market value · +15.1% return · 29 holdings · Consolidating to 20
B13: TAB | C13: LAYER | D13: CONTENTS
B14: PORTFOLIO
B15: 📋 Index | C15: PORTFOLIO | D15: This sheet — overview, portfolio metrics, tab directory.
B16: 📥 Price Hub | C16: PORTFOLIO | D16: ⭐ START HERE for price updates. Update col H (CMP) — all sheets recalculate. Static: Qty/AvgCost/LT Qty (trade only).
B17: 📡 LLM Context | C17: PORTFOLIO | D17: ⭐ START HERE for any review session. Full portfolio state — 27 stocks, live P&L, action codes, catalyst + next trigger. ~350 tokens. Read this before any other sheet.
B18: 📊 Portfolio Brief | C18: PORTFOLIO | D18: All 29 holdings with thesis notes, action tags, P&L.
B19: ⚡ Action Summary | C19: PORTFOLIO | D19: Working checklist — Accumulate / Trim / Hold / Watch.
B20: 🔬 Priority Research | C20: PORTFOLIO | D20: Top 5 + Zydus validation. Live web research. 6 Mar update.
B21: 🗺️ Portfolio Roadmap | C21: PORTFOLIO | D21: Merged: Road to 20 + Consolidation Plan. Wave 1 exits/trims, execution sequence, target 20 portfolio, capital redeployment, Wave 2 flags.
B22: 🔀 Consolidation Plan | C22: PORTFOLIO | D22: v2. BANKBARODA kept. NH sized up. IEX accumulation.
B23: ⚠️ Risk Flags
B24: 🎯 Scenario Analysis
B25: SECTORAL
B26: 🏭 Sector Analysis
B27: 💻 IT Sector Analysis
B28: INDIVIDUAL STOCKS
B29: ⚡ IEX Deep Dive | C29: INDIVIDUAL | D29: ACCUMULATING. Coupling mispriced on timing. Vol +30% YoY. 2.5% yield.
B30: 🔍 IT Deep Dive | C30: INDIVIDUAL | D30: Persistent · eClerx · Sagility — AI disruption, bull/base/bear.
B31: 💊 Medi Assist | C31: INDIVIDUAL | D31: Accumulate. MIT ₹535 anchor. IRDAI cleared ✅. Technical: approaching zone.
B32: 📈 MEDIASSIST Technical | C32: INDIVIDUAL | D32: Chart structure, key levels, 5-tranche entry plan.
B33: 🧨 Chambal Fert | C33: INDIVIDUAL | D33: Hold. TAN April 2026 commissioning confirmed. Wait.
B34: 🏢 EID Parry | C34: INDIVIDUAL | D34: Hold patient. Coromandel 50–60% holdco discount.
B35: 🏦 Utkarsh SFB
B37: Updated 6 Mar 2026 · Research from live web data, company filings, Q3 FY26 earnings ·
B74: 🤖 LLM OPERATING INSTRUCTIONS — Read this first. Determines what to load each session.
B75: SINGLE SOURCE OF TRUTH | C75: 📥 Price Hub col H = CMP. All Mkt Val, P&L, Ret%, Wt% derive from this via formulas. NEVER manually edit calculated fields in other sheets. Writable fields: Price Hub col H (CMP always), col D/E/F (Qty/AvgCost/LTQty on trades only), col M/N (52W H/L optional).
B76: MINIMUM READ SETS | C76: ① PRICE UPDATE: Open 📥 Price Hub → update col H only. ~50 tokens. Done. ② PORTFOLIO REVIEW: Read 📡 LLM Context (~350 tokens) + glance at Price Hub. Optionally ⚡ Action Summary. ③ STOCK DEEP DIVE: Read 📡 LLM Context + that stock's Deep Dive tab only. ④ FULL SESSION: 📡 LLM Context → ⚡ Action Summary → 🔬 Priority Research → stock tabs as needed. ⛔ SKIP UNLESS ASKED: 🗺️ Portfolio Roadmap, , 🎯 Scenario Analysis.
B77: WRITE PROTOCOL | C77: After thesis/action changes: (a) update 📡 LLM Context col ACTION + NOTES for affected stocks, (b) update 📊 Portfolio Brief Notes col, (c) append one row to 📝 Changelog with date + change summary. After price update: verify one spot-check stock in Portfolio Brief shows updated Mkt Val before closing.
B78: SHEET TAXONOMY | C78: 🟡 LIVE — update every session: 📥 Price Hub · 📡 LLM Context · 📝 Changelog 🔵 REFERENCE — update on thesis change: 📊 Portfolio Brief · ⚡ Action Summary · ⚠️ Risk Flags · 🔬 Priority Research ⚪ ARCHIVE — read-once, rarely updated: Portfolio Roadmap · Scenario Analysis · Sector Analysis · Deep Dive tabs

Sheet 📥 Price Hub
B1: 📥 PRICE HUB — Single source of truth | Update CMP here → all sheets recalculate
B2: 🟡 YELLOW = Update these · 🟢 GREEN = Auto-calculated · ⬜ WHITE = Static (update only when you trade) · Last updated: 7 Mar 2026
B4: SYMBOL | C4: SUB-SECTOR | D4: TOTAL QTY | E4: AVG COST ₹ | F4: LT QTY | G4: NON-LT QTY | H4: ⬇ CMP ₹ (UPDATE HERE) | I4: MKT VAL ₹ | J4: INVESTED ₹ | K4: P&L ₹ | L4: RET % | M4: 52W HIGH | N4: 52W LOW | O4: % FROM 52W H | P4: NOTES / DATE
B5: GOLDIETF-E | C5: ETF | D5: 8000 | E5: 84.4748 | F5: 0 | G5: {=D5-F5} -> 8000 | H5: 138.3 | I5: {=D5*H5} -> 1106400 | J5: {=D5*E5} -> 675798.4 | K5: {=I5-J5} -> 430601.6 | L5: {=IF(J5=0,"-",I5/J5-1)} -> 0.63717464 | O5: {=IF(M5="","",H5/M5-1)} | P5: CMP as of 5 Mar 2026
B6: BAJFINANCE | C6: CONSUMER LENDING | D6: 750 | E6: 660 | F6: 0 | G6: {=D6-F6} -> 750 | H6: 945.1 | I6: {=D6*H6} -> 708825 | J6: {=D6*E6} -> 495000 | K6: {=I6-J6} -> 213825 | L6: {=IF(J6=0,"-",I6/J6-1)} -> 0.4319697 | O6: {=IF(M6="","",H6/M6-1)} | P6: CMP as of 5 Mar 2026
B7: UJJIVANSFB | C7: MICROFINANCE | D7: 10074 | E7: 41.8047 | F7: 0 | G7: {=D7-F7} -> 10074 | H7: 54.27 | I7: {=D7*H7} -> 546715.98 | J7: {=D7*E7} -> 421140.55 | K7: {=I7-J7} -> 125575.43 | L7: {=IF(J7=0,"-",I7/J7-1)} -> 0.29817939 | O7: {=IF(M7="","",H7/M7-1)} | P7: CMP as of 5 Mar 2026
B8: COALINDIA | C8: METALS | D8: 1200 | E8: 388.9194 | F8: 0 | G8: {=D8-F8} -> 1200 | H8: 435.15 | I8: {=D8*H8} -> 522180 | J8: {=D8*E8} -> 466703.28 | K8: {=I8-J8} -> 55476.72 | L8: {=IF(J8=0,"-",I8/J8-1)} -> 0.11886936 | O8: {=IF(M8="","",H8/M8-1)} | P8: CMP as of 5 Mar 2026
B9: ICICIBANK | C9: BANKING | D9: 375 | E9: 1154.2536 | F9: 350 | G9: {=D9-F9} -> 25 | H9: 1365.4 | I9: {=D9*H9} -> 512025 | J9: {=D9*E9} -> 432845.1 | K9: {=I9-J9} -> 79179.9 | L9: {=IF(J9=0,"-",I9/J9-1)} -> 0.18292895 | O9: {=IF(M9="","",H9/M9-1)} | P9: CMP as of 5 Mar 2026
B10: HOMEFIRST | C10: HOUSING FINANCE | D10: 441 | E10: 934.6512 | F10: 441 | G10: {=D10-F10} -> 0 | H10: 1074.4 | I10: {=D10*H10} -> 473810.4 | J10: {=D10*E10} -> 412181.18 | K10: {=I10-J10} -> 61629.221 | L10: {=IF(J10=0,"-",I10/J10-1)} -> 0.14951974 | O10: {=IF(M10="","",H10/M10-1)} | P10: CMP as of 5 Mar 2026
B11: CARYSIL | C11: FMCG | D11: 550 | E11: 743.8698 | F11: 425 | G11: {=D11-F11} -> 125 | H11: 859.1 | I11: {=D11*H11} -> 472505 | J11: {=D11*E11} -> 409128.39 | K11: {=I11-J11} -> 63376.61 | L11: {=IF(J11=0,"-",I11/J11-1)} -> 0.15490641 | O11: {=IF(M11="","",H11/M11-1)} | P11: CMP as of 5 Mar 2026
B12: BANKBARODA | C12: BANKING | D12: 1500 | E12: 241.5191 | F12: 0 | G12: {=D12-F12} -> 1500 | H12: 299.3 | I12: {=D12*H12} -> 448950 | J12: {=D12*E12} -> 362278.65 | K12: {=I12-J12} -> 86671.35 | L12: {=IF(J12=0,"-",I12/J12-1)} -> 0.23923946 | O12: {=IF(M12="","",H12/M12-1)} | P12: CMP as of 5 Mar 2026
B13: CREDITACC | C13: MICROFINANCE | D13: 350 | E13: 961.5244 | F13: 275 | G13: {=D13-F13} -> 75 | H13: 1225.8 | I13: {=D13*H13} -> 429030 | J13: {=D13*E13} -> 336533.54 | K13: {=I13-J13} -> 92496.46 | L13: {=IF(J13=0,"-",I13/J13-1)} -> 0.27485064 | O13: {=IF(M13="","",H13/M13-1)} | P13: CMP as of 5 Mar 2026
B14: LT | C14: ENGINEERING & CAPITAL GOODS | D14: 110 | E14: 3614.1977 | F14: 0 | G14: {=D14-F14} -> 110 | H14: 3882.6 | I14: {=D14*H14} -> 427086 | J14: {=D14*E14} -> 397561.75 | K14: {=I14-J14} -> 29524.253 | L14: {=IF(J14=0,"-",I14/J14-1)} -> 0.074263314 | O14: {=IF(M14="","",H14/M14-1)} | P14: CMP as of 5 Mar 2026
B15: NH | C15: HEALTHCARE | D15: 240 | E15: 1336.4402 | F15: 200 | G15: {=D15-F15} -> 40 | H15: 1744 | I15: {=D15*H15} -> 418560 | J15: {=D15*E15} -> 320745.65 | K15: {=I15-J15} -> 97814.352 | L15: {=IF(J15=0,"-",I15/J15-1)} -> 0.30495925 | O15: {=IF(M15="","",H15/M15-1)} | P15: CMP as of 5 Mar 2026
B16: HDFCBANK | C16: BANKING | D16: 450 | E16: 626.6593 | F16: 175 | G16: {=D16-F16} -> 275 | H16: 868.65 | I16: {=D16*H16} -> 390892.5 | J16: {=D16*E16} -> 281996.68 | K16: {=I16-J16} -> 108895.82 | L16: {=IF(J16=0,"-",I16/J16-1)} -> 0.38615991 | O16: {=IF(M16="","",H16/M16-1)} | P16: CMP as of 5 Mar 2026
... B31: SGB-COMBINED | C31: SOVEREIGN GOLD BOND | D31: 6 | E31: 16262.96 | F31: 0 | G31: {=D31-F31} -> 6 | H31: 16392.83 | I31: {=D31*H31} -> 98356.98 | J31: {=D31*E31} -> 97577.76 | K31: {=I31-J31} -> 779.22 | L31: {=IF(J31=0,"-",I31/J31-1)} -> 0.0079856312 | O31: {=IF(M31="","",H31/M31-1)} | P31: 2 SGBs: 4 units Dec-2031 + 2 units Apr-2028. Tax-free capital gains at maturity. Zero action.
B34: TOTAL | I34: {=SUM(I5:I33)} -> 10119824 | J34: {=SUM(J5:J33)} -> 8790005.6 | K34: {=SUM(K5:K33)} -> 1329818.3 | L34: {=I34/J34-1} -> 0.15128753

Sheet 📡 LLM Context
B1: 📡 LLM CONTEXT — Full portfolio state in one read | ~350 tokens | Formula-linked to Price Hub
B2: 🟢 GREEN = ACCUMULATE | 🟡 AMBER = TRIM | 🔵 BLUE = HOLD | 🟠 ORANGE = WATCH | 🟣 PURPLE = RE-ENTRY | Mkt Val, P&L, Ret% update automatically when Price Hub CMP changes
B4: SYM | C4: SECTOR | D4: ACTION | E4: WT% | F4: CMP ₹ | G4: AVG ₹ | H4: RET% | I4: MKT VAL ₹ | J4: P&L ₹ | K4: QTY | L4: LT QTY | M4: KEY CATALYST / THESIS | N4: NEXT TRIGGER / WATCH
B5: GOLDIETF-E | C5: ETF | D5: HOLD FULL | E5: {='📊 Portfolio Brief'!D11} -> 0.10932997 | F5: {=_xlfn.IFERROR(VLOOKUP(B5,'📥 Price Hub'!$B$5:$H$34,7,0),0)} -> 138.3 | G5: 84.4748 | H5: {='📊 Portfolio Brief'!J11} -> 0.63717464 | I5: {='📊 Portfolio Brief'!H11} -> 1106400 | J5: {='📊 Portfolio Brief'!I11} -> 430601.6 | K5: 8000 | L5: 0 | M5: Central bank demand, dollar re-rating, geopolitical hedge | N5: None — structural hold full position
B6: BAJFINANCE | C6: CONSUMER LENDING | D6: HOLD | E6: {='📊 Portfolio Brief'!D12} -> 0.070043215 | F6: {=_xlfn.IFERROR(VLOOKUP(B6,'📥 Price Hub'!$B$5:$H$34,7,0),0)} -> 945.1 | G6: 660 | H6: {='📊 Portfolio Brief'!J12} -> 0.4319697 | I6: {='📊 Portfolio Brief'!H12} -> 708825 | J6: {='📊 Portfolio Brief'!I12} -> 213825 | K6: 750 | L6: 0 | M6: Consumer lending market leader, 43% gain, strong franchise | N6: Quarterly earnings watch
B7: UJJIVANSFB | C7: MICROFINANCE | D7: HOLD — MONITOR | E7: {='📊 Portfolio Brief'!D13} -> 0.054024258 | F7: {=_xlfn.IFERROR(VLOOKUP(B7,'📥 Price Hub'!$B$5:$H$34,7,0),0)} -> 54.27 | G7: 41.8047 | H7: {='📊 Portfolio Brief'!J13} -> 0.29817939 | I7: {='📊 Portfolio Brief'!H13} -> 546715.98 | J7: {='📊 Portfolio Brief'!I13} -> 125575.43 | K7: 10074 | L7: 0 | M7: MFI stress cycle manageable; collection efficiency improving | N7: NPA trajectory + collection efficiency Q4
B8: COALINDIA | C8: METALS | D8: TRIM CANDIDATE | E8: {='📊 Portfolio Brief'!D14} -> 0.051599712 | F8: {=_xlfn.IFERROR(VLOOKUP(B8,'📥 Price Hub'!$B$5:$H$34,7,0),0)} -> 435.15 | G8: 388.9194 | H8: {='📊 Portfolio Brief'!J14} -> 0.11886936 | I8: {='📊 Portfolio Brief'!H14} -> 522180 | J8: {='📊 Portfolio Brief'!I14} -> 55476.72 | K8: 1200 | L8: 0 | M8: PSU dividend play — upside capped by govt pricing | N8: Trim on any rally; redeploy to conviction names
B9: ICICIBANK | C9: BANKING | D9: HOLD | E9: {='📊 Portfolio Brief'!D15} -> 0.050596236 | F9: {=_xlfn.IFERROR(VLOOKUP(B9,'📥 Price Hub'!$B$5:$H$34,7,0),0)} -> 1365.4 | G9: 1154.2536 | H9: {='📊 Portfolio Brief'!J15} -> 0.18292895 | I9: {='📊 Portfolio Brief'!H15} -> 512025 | J9: {='📊 Portfolio Brief'!I15} -> 79179.9 | K9: 375 | L9: 350 | M9: Best-in-class private bank, consistent compounder | N9: Hold through rate cycle
B10: HOMEFIRST | C10: HOUSING FINANCE | D10: HOLD | E10: {='📊 Portfolio Brief'!D16} -> 0.046820024 | F10: {=_xlfn.IFERROR(VLOOKUP(B10,'📥 Price Hub'!$B$5:$H$34,7,0),0)} -> 1074.4 | G10: 934.6512 | H10: {='📊 Portfolio Brief'!J16} -> 0.14951974 | I10: {='📊 Portfolio Brief'!H16} -> 473810.4 | J10: {='📊 Portfolio Brief'!I16} -> 61629.221 | K10: 441 | L10: 441 | M10: Affordable housing finance, all 441 shares LT | N10: Housing credit cycle watch
B11: CARYSIL | C11: FMCG | D11: HOLD | E11: {='📊 Portfolio Brief'!D17} -> 0.04669103 | F11: {=_xlfn.IFERROR(VLOOKUP(B11,'📥 Price Hub'!$B$5:$H$34,7,0),0)} -> 859.1 | G11: 743.8698 | H11: {='📊 Portfolio Brief'!J17} -> 0.15490641 | I11: {='📊 Portfolio Brief'!H17} -> 472505 | J11: {='📊 Portfolio Brief'!I17} -> 63376.61 | K11: 550 | L11: 425 | M11: Global quartz sink exporter, niche moat | N11: Export order momentum + US tariff impact
B12: BANKBARODA | C12: BANKING | D12: HOLD | E12: {='📊 Portfolio Brief'!D18} -> 0.04436342 | F12: {=_xlfn.IFERROR(VLOOKUP(B12,'📥 Price Hub'!$B$5:$H$34,7,0),0)} -> 299.3 | G12: 241.5191 | H12: {='📊 Portfolio Brief'!J18} -> 0.23923946 | I12: {='📊 Portfolio Brief'!H18} -> 448950 | J12: {='📊 Portfolio Brief'!I18} -> 86671.35 | K12: 1500 | L12: 0 | M12: PSU bank; sole PSU momentum play retained | N12: Monitor credit costs quarterly
B13: CREDITACC | C13: MICROFINANCE | D13: HOLD | E13: {='📊 Portfolio Brief'!D19} -> 0.042395007 | F13: {=_xlfn.IFERROR(VLOOKUP(B13,'📥 Price Hub'!$B$5:$H$34,7,0),0)} -> 1225.8 | G13: 961.5244 | H13: {='📊 Portfolio Brief'!J19} -> 0.27485064 | I13: {='📊 Portfolio Brief'!H19} -> 429030 | J13: {='📊 Portfolio Brief'!I19} -> 92496.46 | K13: 350 | L13: 275 | M13: Quality MFI, conservative underwriting, recovering | N13: MFI sector NPA trend Q4 FY26
B14: LT | C14: ENGINEERING & CAPITAL GOODS | D14: TRIM CANDIDATE | E14: {='📊 Portfolio Brief'!D20} -> 0.042202908 | F14: {=_xlfn.IFERROR(VLOOKUP(B14,'📥 Price Hub'!$B$5:$H$34,7,0),0)} -> 3882.6 | G14: 3614.1977 | H14: {='📊 Portfolio Brief'!J20} -> 0.074263314 | I14: {='📊 Portfolio Brief'!H20} -> 427086 | J14: {='📊 Portfolio Brief'!I20} -> 29524.253 | K14: 110 | L14: 0 | M14: Infra/engineering; +7% underwhelming for hold period | N14: Trim on rally; no LT shares, no friction
B15: NH | C15: HEALTHCARE | D15: HOLD | E15: {='📊 Portfolio Brief'!D21} -> 0.041360404 | F15: {=_xlfn.IFERROR(VLOOKUP(B15,'📥 Price Hub'!$B$5:$H$34,7,0),0)} -> 1744 | G15: 1336.4402 | H15: {='📊 Portfolio Brief'!J21} -> 0.30495925 | I15: {='📊 Portfolio Brief'!H21} -> 418560 | J15: {='📊 Portfolio Brief'!I21} -> 97814.352 | K15: 240 | L15: 200 | M15: Narayana healthcare compounder, Cayman asset-light inflecting | N15: Cayman revenue contribution H2 FY26+
B16: HDFCBANK | C16: BANKING | D16: HOLD | E16: {='📊 Portfolio Brief'!D22} -> 0.038626413 | F16: {=_xlfn.IFERROR(VLOOKUP(B16,'📥 Price Hub'!$B$5:$H$34,7,0),0)} -> 868.65 | G16: 626.6593 | H16: {='📊 Portfolio Brief'!J22} -> 0.38615991 | I16: {='📊 Portfolio Brief'!H22} -> 390892.5 | J16: {='📊 Portfolio Brief'!I22} -> 108895.82 | K16: 450 | L16: 175 | M16: Largest private bank, merger integration largely complete | N16: Credit growth + NIM recovery trajectory
... B31: SGB-COMBINED | C31: SOVEREIGN GOLD BOND | D31: HOLD TO MATURITY | E31: {='📊 Portfolio Brief'!D37} -> 0.0097192383 | F31: {=_xlfn.IFERROR(VLOOKUP(B31,'📥 Price Hub'!$B$5:$H$34,7,0),0)} -> 16392.83 | G31: 16262.96 | H31: {='📊 Portfolio Brief'!J37} -> 0 | I31: {='📊 Portfolio Brief'!H37} -> 98356.98 | J31: {='📊 Portfolio Brief'!I37} -> 779.22 | K31: 6 | L31: 0 | M31: 2 SGBs combined. Tax-free at maturity. | N31: Hold both to maturity — zero action
B34: TOTAL | H34: {=J34/SUM('📊 Portfolio Brief'!G11:G39)} -> 0.15128753 | I34: {=SUM(I5:I33)} -> 10119824 | J34: {=SUM(J5:J33)} -> 1329818.3

Sheet 📊 Portfolio Brief
B1: PORTFOLIO BRIEF — ALL HOLDINGS ANNOTATED
B2: BAJFINANCE avg corrected to ₹660 · Finance broken to sub-sectors · IT sector reviewed post AI-disruption analysis
B4: TOTAL INVESTED | E4: MARKET VALUE | H4: UNREALISED P&L | K4: RETURN | M4: # HOLDINGS
B5: {=G40} -> 8790005.6 | E5: ₹10,119,879 | H5: {=H40} -> 10119824 | K5: {=I40} -> 1329818.3 | M5: {=I40/G40} -> 0.15128753
B9: ALL HOLDINGS
B10: Symbol | C10: Sub-Sector | D10: Wt% | E10: Avg Cost | F10: CMP | G10: Invested (₹) | H10: Mkt Val (₹) | I10: P&L (₹) | J10: Ret % | K10: LT Qty | L10: Action | M10: Tag | N10: Notes
B11: GOLDIETF-E | C11: ETF | D11: {=H11/$H$40} -> 0.10932997 | E11: 84.4748 | F11: {=_xlfn.IFERROR(VLOOKUP(B11,'📥 Price Hub'!$B$5:$H$34,7,0),0)} -> 138.3 | G11: 675798.4 | H11: {=_xlfn.IFERROR(VLOOKUP(B11,'📥 Price Hub'!$B$5:$D$34,3,0)*F11,0)} -> 1106400 | I11: {=H11-G11} -> 430601.6 | J11: {=IF(G11=0,0,H11/G11-1)} -> 0.63717464 | K11: 0 | L11: HOLD FULL | M11: ⭐ CORE | N11: Structural hold. Central bank demand, dollar re-rating, geopolitical hedge intact. ~11% weight is intentional. No trim despite size — gold is in a structural demand scenario.
B12: BAJFINANCE | C12: CONSUMER LENDING | D12: {=H12/$H$40} -> 0.070043215 | E12: 660 | F12: {=_xlfn.IFERROR(VLOOKUP(B12,'📥 Price Hub'!$B$5:$H$34,7,0),0)} -> 945.1 | G12: 495000 | H12: {=_xlfn.IFERROR(VLOOKUP(B12,'📥 Price Hub'!$B$5:$D$34,3,0)*F12,0)} -> 708825 | I12: {=H12-G12} -> 213825 | J12: {=IF(G12=0,0,H12/G12-1)} -> 0.4319697 | K12: 0 | L12: HOLD | M12: ✅ RUNNING | N12: Avg corrected to ₹660. CMP ₹945 = ~43% gain. Consumer lending market leader, strong franchise.
B13: UJJIVANSFB | C13: MICROFINANCE | D13: {=H13/$H$40} -> 0.054024258 | E13: 41.8047 | F13: {=_xlfn.IFERROR(VLOOKUP(B13,'📥 Price Hub'!$B$5:$H$34,7,0),0)} -> 54.27 | G13: 421140.55 | H13: {=_xlfn.IFERROR(VLOOKUP(B13,'📥 Price Hub'!$B$5:$D$34,3,0)*F13,0)} -> 546715.98 | I13: {=H13-G13} -> 125575.43 | J13: {=IF(G13=0,0,H13/G13-1)} -> 0.29817939 | K13: 0 | L13: HOLD — MONITOR | M13: 👁 WATCH | N13: Ujjivan SFB. MFI stress cycle. Monitor NPA trajectory and collection efficiency quarterly.
B14: COALINDIA | C14: METALS | D14: {=H14/$H$40} -> 0.051599712 | E14: 388.9194 | F14: {=_xlfn.IFERROR(VLOOKUP(B14,'📥 Price Hub'!$B$5:$H$34,7,0),0)} -> 435.15 | G14: 466703.28 | H14: {=_xlfn.IFERROR(VLOOKUP(B14,'📥 Price Hub'!$B$5:$D$34,3,0)*F14,0)} -> 522180 | I14: {=H14-G14} -> 55476.72 | J14: {=IF(G14=0,0,H14/G14-1)} -> 0.11886936 | K14: 0 | L14: TRIM CANDIDATE | M14: ✂️ TRIM | N14: PSU with government-capped upside. Energy transition headwind even if decade away. No LT shares — clean trim available. Redeploy into conviction names.
B15: ICICIBANK | C15: BANKING | D15: {=H15/$H$40} -> 0.050596236 | E15: 1154.2536 | F15: {=_xlfn.IFERROR(VLOOKUP(B15,'📥 Price Hub'!$B$5:$H$34,7,0),0)} -> 1365.4 | G15: 432845.1 | H15: {=_xlfn.IFERROR(VLOOKUP(B15,'📥 Price Hub'!$B$5:$D$34,3,0)*F15,0)} -> 512025 | I15: {=H15-G15} -> 79179.9 | J15: {=IF(G15=0,0,H15/G15-1)} -> 0.18292895 | K15: 350 | L15: HOLD | M15: ✅ RUNNING | N15: Top-tier private bank. Consistent compounder. Core holding.
B16: HOMEFIRST | C16: HOUSING FINANCE | D16: {=H16/$H$40} -> 0.046820024 | E16: 934.6512 | F16: {=_xlfn.IFERROR(VLOOKUP(B16,'📥 Price Hub'!$B$5:$H$34,7,0),0)} -> 1074.4 | G16: 412181.18 | H16: {=_xlfn.IFERROR(VLOOKUP(B16,'📥 Price Hub'!$B$5:$D$34,3,0)*F16,0)} -> 473810.4 | I16: {=H16-G16} -> 61629.221 | J16: {=IF(G16=0,0,H16/G16-1)} -> 0.14951974 | K16: 441 | L16: HOLD | M16: ✅ RUNNING | N16: All 441 shares LT. Affordable housing finance. Full LTCG on any exit.
B17: CARYSIL | C17: FMCG | D17: {=H17/$H$40} -> 0.04669103 | E17: 743.8698 | F17: {=_xlfn.IFERROR(VLOOKUP(B17,'📥 Price Hub'!$B$5:$H$34,7,0),0)} -> 859.1 | G17: 409128.39 | H17: {=_xlfn.IFERROR(VLOOKUP(B17,'📥 Price Hub'!$B$5:$D$34,3,0)*F17,0)} -> 472505 | I17: {=H17-G17} -> 63376.61 | J17: {=IF(G17=0,0,H17/G17-1)} -> 0.15490641 | K17: 425 | L17: HOLD | M17: ✅ RUNNING | N17: Quartz kitchen sinks niche global exporter. 425/550 shares LT — LTCG friction on majority. Ongoing story.
B18: BANKBARODA | C18: BANKING | D18: {=H18/$H$40} -> 0.04436342 | E18: 241.5191 | F18: {=_xlfn.IFERROR(VLOOKUP(B18,'📥 Price Hub'!$B$5:$H$34,7,0),0)} -> 299.3 | G18: 362278.65 | H18: {=_xlfn.IFERROR(VLOOKUP(B18,'📥 Price Hub'!$B$5:$D$34,3,0)*F18,0)} -> 448950 | I18: {=H18-G18} -> 86671.35 | J18: {=IF(G18=0,0,H18/G18-1)} -> 0.23923946 | K18: 0 | L18: HOLD | M18: ✅ RUNNING | N18: PSU bank. +24% gain. Decent run. Lower conviction vs private banks but no exit reason.
B19: CREDITACC | C19: MICROFINANCE | D19: {=H19/$H$40} -> 0.042395007 | E19: 961.5244 | F19: {=_xlfn.IFERROR(VLOOKUP(B19,'📥 Price Hub'!$B$5:$H$34,7,0),0)} -> 1225.8 | G19: 336533.54 | H19: {=_xlfn.IFERROR(VLOOKUP(B19,'📥 Price Hub'!$B$5:$D$34,3,0)*F19,0)} -> 429030 | I19: {=H19-G19} -> 92496.46 | J19: {=IF(G19=0,0,H19/G19-1)} -> 0.27485064 | K19: 275 | L19: HOLD | M19: ✅ RUNNING | N19: CreditAccess Grameen. Quality MFI, conservative underwriting. 275/350 shares LT.
B20: LT | C20: ENGINEERING & CAPITAL GOODS | D20: {=H20/$H$40} -> 0.042202908 | E20: 3614.1977 | F20: {=_xlfn.IFERROR(VLOOKUP(B20,'📥 Price Hub'!$B$5:$H$34,7,0),0)} -> 3882.6 | G20: 397561.75 | H20: {=_xlfn.IFERROR(VLOOKUP(B20,'📥 Price Hub'!$B$5:$D$34,3,0)*F20,0)} -> 427086 | I20: {=H20-G20} -> 29524.253 | J20: {=IF(G20=0,0,H20/G20-1)} -> 0.074263314 | K20: 0 | L20: TRIM CANDIDATE | M20: ✂️ TRIM | N20: +7% for holding period is underwhelming for a large cap. No LT shares, no tax friction. Partial trim frees capital.
B21: NH | C21: HEALTHCARE | D21: {=H21/$H$40} -> 0.041360404 | E21: 1336.4402 | F21: {=_xlfn.IFERROR(VLOOKUP(B21,'📥 Price Hub'!$B$5:$H$34,7,0),0)} -> 1744 | G21: 320745.65 | H21: {=_xlfn.IFERROR(VLOOKUP(B21,'📥 Price Hub'!$B$5:$D$34,3,0)*F21,0)} -> 418560 | I21: {=H21-G21} -> 97814.352 | J21: {=IF(G21=0,0,H21/G21-1)} -> 0.30495925 | K21: 200 | L21: HOLD | M21: ⭐ CORE | N21: Narayana Hrudayalaya. 200/240 shares LT. Healthcare delivery compounder, asset-light model. Multi-year story.
B22: HDFCBANK | C22: BANKING | D22: {=H22/$H$40} -> 0.038626413 | E22: 626.6593 | F22: {=_xlfn.IFERROR(VLOOKUP(B22,'📥 Price Hub'!$B$5:$H$34,7,0),0)} -> 868.65 | G22: 281996.68 | H22: {=_xlfn.IFERROR(VLOOKUP(B22,'📥 Price Hub'!$B$5:$D$34,3,0)*F22,0)} -> 390892.5 | I22: {=H22-G22} -> 108895.82 | J22: {=IF(G22=0,0,H22/G22-1)} -> 0.38615991 | K22: 175 | L22: HOLD | M22: ✅ RUNNING | N22: Largest private bank. Merger integration largely complete. Core holding.
... B36: ECLERX | C36: SOFTWARE SERVICES | D36: {=H36/$H$40} -> 0.012735992 | E36: 3310.275 | F36: {=_xlfn.IFERROR(VLOOKUP(B36,'📥 Price Hub'!$B$5:$H$34,7,0),0)} -> 3222.15 | G36: 132411 | H36: {=_xlfn.IFERROR(VLOOKUP(B36,'📥 Price Hub'!$B$5:$D$34,3,0)*F36,0)} -> 128886 | I36: {=H36-G36} -> -3525 | J36: {=IF(G36=0,0,H36/G36-1)} -> -0.026621655 | K36: 0 | L36: HOLD — CONSIDER ADD | M36: 👁 CONSIDER ADD | N36: Domain-specialist KPO in capital markets analytics. NOT generic IT. Promoter at 54.5% bought back at ₹4,800 vs CMP ₹3,222 — the strongest possible signal. AI risk much lower than peers (domain judgment required). Consider modest add.
B37: SGB-COMBINED | C37: SOVEREIGN GOLD BOND | D37: {=H37/$H$40} -> 0.0097192383 | E37: 16262.96 | F37: {=_xlfn.IFERROR(VLOOKUP(B37,'📥 Price Hub'!$B$5:$H$34,7,0),0)} -> 16392.83 | G37: 97577.76 | H37: {=_xlfn.IFERROR(VLOOKUP(B37,'📥 Price Hub'!$B$5:$D$34,3,0)*F37,0)} -> 98356.98 | I37: {=H37-G37} -> 779.22 | J37: 0 | K37: HOLD TO MATURITY | L37: 🔒 MATURITY | M37: 🔒 MATURITY | N37: 2 SGBs: 4 units Dec-2031 + 2 units Apr-2028. Tax-free capital gains at maturity. Zero action.
B40: TOTAL | D40: 1 | G40: {=SUM(G11:G39)} -> 8790005.6 | H40: {=SUM(H11:H39)} -> 10119824 | I40: {=H40-G40} -> 1329818.3 | J40: {=I40/G40} -> 0.15128753

Sheet ⚡ Action Summary
B1: ACTION SUMMARY — WORKING CHECKLIST
B2: Numbers removed — live P&L/Wt% in 📡 LLM Context and 📊 Portfolio Brief. This sheet: actions + rationale only.
B4: 🎯 ACCUMULATE — BUILD POSITIONS
B5: Symbol | C5: Sub-Sector | H5: Action Note / Rationale
B6: UTKARSHBNK | C6: MICROFINANCE | H6: ACCUMULATE
B7: MEDIASSIST | C7: SOFTWARE SERVICES | H7: ACCUMULATE
B8: MEDIASSIST: target 6–7%, tranches now/May/ED closure. UTKARSHBNK: target 3–4%, turnaround confirmed by data. IEX: target 3–4%, accumulate ₹115–120; retain all 1,750 shares. See ⚡ IEX Deep Dive.
B10: ✂️ TRIM — FREE UP CAPITAL
B11: Symbol | C11: Sub-Sector | H11: Action Note / Rationale
B12: COALINDIA | C12: METALS | H12: TRIM CANDIDATE
B13: LT | C13: ENGINEERING & CAPITAL GOODS | H13: TRIM CANDIDATE
B15: CoalIndia + LT: partial trims for capital redeployment. Combined ~₹3–5L.
B17: 📈 TRIM ON STRENGTH
B18: Symbol | C18: Sub-Sector | H18: Action Note / Rationale
B19: SILVERCASE-E | C19: ETF | H19: TRIM ON STRENGTH
B20: Trim silver toward ₹30–32 on upmoves. Keep gold full.
B22: ⭐ CORE — DO NOTHING
B23: Symbol | C23: Sub-Sector | H23: Action Note / Rationale
B24: GOLDIETF-E | C24: ETF | H24: HOLD FULL
B25: NH | C25: HEALTHCARE | H25: HOLD
B26: CHAMBLFERT | C26: FERTILIZERS | H26: HOLD — WAIT
B27: EIDPARRY | C27: FMCG | H27: HOLD — PATIENT
B28: KIRLOSENG | C28: ENGINEERING & CAPITAL GOODS | H28: HOLD
B29: GOLDIETF: structural hold, no trim. CHAMBLFERT: wait for TAN revenue print. EIDPARRY: holdco patience trade.
B31: ✅ HOLD — RUNNING
B32: Symbol | C32: Sub-Sector | H32: Action Note / Rationale
B33: BAJFINANCE | C33: CONSUMER LENDING | H33: HOLD
B34: ICICIBANK | C34: BANKING | H34: HOLD
B35: HOMEFIRST | C35: HOUSING FINANCE | H35: HOLD
B36: CARYSIL | C36: FMCG | H36: HOLD
B37: BANKBARODA | C37: BANKING | H37: HOLD
B38: CREDITACC | C38: MICROFINANCE | H38: HOLD
B39: HDFCBANK | C39: BANKING | H39: HOLD
B40: FEDFINA | C40: HOUSING FINANCE | H40: HOLD
B41: Ongoing thesis, performing or recovering. Review quarterly.
B43: 👁 WATCH — DECISION PENDING
B44: Symbol | C44: Sub-Sector | H44: Action Note / Rationale
B45: UJJIVANSFB | C45: MICROFINANCE | H45: HOLD — MONITOR
B46: ASTRAMICRO | C46: DEFENCE | H46: WATCH — REVIEW
B47: CAMS | C47: MARKET INFRASTRUCTURE | H47: WATCH
...

Sheet 🔬 Priority Research
B2: 🔬 PRIORITY RESEARCH — TOP 5 ACTIONS | Updated 6 March 2026
B3: Secondary reasoning and web research appended post-session. Source: Live web data, company filings, earnings calls.
B5: STOCK | C5: PRIORITY | D5: ACTION | E5: VERDICT | F5: RESEARCH NOTES — 6 Mar 2026
B7: ① MEDIASSIST — ACCUMULATE | Target 6–7%
B8: ED Risk Update | C8: ED search (April 4, 2025, Ranchi) is unchanged in status — management stated no adverse impact in Q3 FY26 filings. No escalation to formal charges or IRDAI action since the original search. This tail risk remains OPEN but has NOT worsened.
B9: ⚠️ NEW: GST Resolution | C9: Medi Assist TPA paid ₹4.83Cr to GST authorities (Feb 16–Mar 2, 2026 search) to avoid penalties. This is a POSITIVE development — the GST matter closed via payment rather than formal proceedings. Removes one uncertainty from the bear case.
B10: Q3 FY26 Results | C10: Consolidated revenue ₹2,396Cr (+64% YoY, Paramount consolidation driving bulk). Consolidated PAT ₹41Cr (down 86% YoY) — distorted by exceptional items: ₹37.68Cr cybersecurity costs, ₹33.27Cr labor codes, ₹71Cr advance pending reconciliation. STANDALONE PAT ₹118Cr (+222% YoY) — the clean business is doing well. 9M standalone PAT ₹374.92Cr. Company became debt-free from Jan 2026 confirmed.
B11: ⚠️ IRDAI Licence Renewal | C11: IRDAI TPA Licence (No. 003) validity: 20 March 2026 — expiry THIS MONTH. This is routine renewal but must be confirmed. If not renewed or delayed, it is an existential trigger. Track for confirmation by March 20.
B12: Integration Milestones | C12: Feb 6, 2026: Board approved Scheme of Merger — Paramount TPA (PHTPA) to be absorbed into MAITPA. Integration is proceeding structurally. Promoter reclassification from Promoter Group to Public filed Jan 2026 (SEBI Reg 31A) — not a red flag, routine corporate governance action.
B13: New Expansion | C13: Feb 27, 2026: Partnership with LawtonAsia to deploy AI health-insurance platform in Thailand. Implementation started, go-live expected soon. Small but signals the platform has export potential beyond India.
B14: 📌 Revised Action Note | C14: ACCUMULATE — thesis strengthened, not weakened. GST resolved. ED status quo (no escalation). IRDAI renewal this month is the single most important binary to track. Tranches: NOW (current ~₹340) → Q4 results May → ED closure. Add IRDAI renewal confirmation as Tranche 1 prerequisite watch. MIT underwater at ₹535 remains anchor.
B16: ② CHAMBLFERT — HOLD / WAIT | TAN April 2026
B17: TAN Status — CONFIRMED | C17: Q3 FY26 earnings call (Feb 13, 2026): Management REAFFIRMED April 30, 2026 commissioning. No further slippage. Engineering 99.86% done, procurement 99.80%, construction 88.01%. Total completion 92.65%. ₹1,184Cr spent of ₹1,645Cr. Catalyst is ON SCHEDULE and approaching fast.
B18: Q3 FY26 Financials | C18: Standalone revenue ₹5,898Cr (+20% YoY), EBITDA ₹821Cr (+6%), PAT ₹565Cr (+12%). 9M revenue +27%, PAT +16%. Base business performing well. CPC & Specialty Nutrients +33% YoY. Complex fertilisers +81% YoY. Biologicals growing.
B19: ⚠️ Margin Compression | C19: EBITDA margin Q3: 13.92% vs 15.82% prior year (–190bps). 9M: 13.46% vs 16.34% prior year. Driven by input cost pressure (sulfur, phosphoric acid, ammonia). Not alarming — base urea margins have ceiling (NIP-2012). The TAN business (no subsidy, no margin cap) is the structural fix. Monitor but within acceptable range.
B20: Gadepan-II Shutdown | C20: Planned maintenance shutdown for Gadepan-II plant: Feb 20, 2026, ~30-35 days. This will create a small Q4 volume dip for urea — already flagged by management. Non-event, scheduled maintenance. Watch Q4 FY26 results for confirmation.
B21: Future Growth Signals | C21: ICRA reaffirmed TAN commercial operations April 2026. NIP-2012 policy (G-3 plant) expires Dec 2026 — policy uncertainty risk on urea returns, but TAN addresses this by reducing subsidy dependence. IMACID JV capacity expanding from 5 to 7 lakh MT P2O5 by Dec 2026. Management exploring vertical and horizontal TAN expansion (LDAN capacity already provisioned in plant design). Agreement with TERI for advanced agricultural solutions.
B22: 📌 Revised Action Note | C22: HOLD — DO NOTHING. TAN catalyst is on track and imminent. Conviction HIGH. Watch for: (a) any April delay announcements, (b) first TAN revenue in Q1/Q2 FY27 results. The ₹654 peak hit in Apr 2025 on TAN expectations is likely to revisit once first revenue prints. Hold full 850 shares.
B24: ③ UTKARSHBNK — ACCUMULATE | Target 3–4%
B25: Q3 FY26 — Net Loss ₹375Cr | C25: Net loss ₹375Cr for Q3; 9M loss ₹963Cr. This is KNOWN stress — fully provisioned. The loss is the price of front-loading provisions. Pre-provision operating loss only ₹44Cr (small). Loan portfolio contracted 3.9% YoY to ₹18,306Cr — intentional, not distress.
B26: ✅ DPD Inflection Confirmed | C26: JLG 1-to-90 DPD: ₹378Cr (Oct 2025) → <₹50Cr (Jan 2026). 87% reduction in 3 months. 1-to-30 DPD (freshest stress): ₹170Cr → <₹50Cr. These numbers are REAL and non-reversible for the cohort already cleared. The October 2025 festival season was the absolute stress peak.
B27: ✅ Disbursements Recovering | C27: Monthly disbursements: ₹800Cr (Oct) → ₹1,000Cr (Nov) → ₹1,100Cr (Dec) → ₹1,200Cr+ (Jan 2026). 50% growth in 3 months. Critically: JLG segment itself started growing again from January — first time in multiple quarters.
B28: Collection Efficiency | C28: X-bucket efficiency: 99.1% overall Q3; 99.5% JLG-specific in December. January even higher. Management guidance: will not fall below 99.5% again. CAR 20.1% (post ₹950Cr rights). LCR 207%, surplus liquidity ₹4,700Cr. This bank is not a capital risk.
B29: Asset Mix Transformation | C29: Secured lending: 50% of loan book (from 41% a year ago, 10% in early years). JLG exposure down from 90% (FY20) to 33% now. This bank structurally CANNOT repeat the same MFI stress — the business model is changing. Deposits +4.5% YoY despite stress; retail term deposits +23.8% YoY; CASA ratio improved to 21.9%.
B30: ⚠️ Management Changes | C30: CHRO Hitain Sharma resigned Feb 27, 2026. Director Muralidharan Rajamani ceased Mar 2, 2026 (5-year term completion — routine). Worth monitoring for further senior exits, but no red flag yet. Smart money (FIIs +10.12%, DIIs +7.35%) accumulated in Q3 — the same quarter of worst-ever quarterly loss.
B31: 📌 Revised Action Note | C31: ACCUMULATE — conviction STRONGER. Q4 FY26 is expected to be first visible QoQ AUM growth on pre-write-off basis (catalyst: next quarterly result ~May 2026). Add in tranches each quarter clean data prints. Current weight ~2.9%. Target 3–4%. Gross NPA still at 11% — this is the legacy tail, not new slippages. Monitor: monthly collection data, Q4 JLG NPA formation.
B33: ④ ASTRAMICRO — THESIS DELAYED, NOT BROKEN | Hold, do NOT harvest
B34: Q3 FY26 — Sequential Recovery | C34: Standalone revenue ₹258Cr (+0.66% YoY, but +21.28% QoQ). Q2 was the trough. EBITDA ₹80Cr, margin 30.9% standalone / 31.7% consolidated — BEST margin in many quarters. PAT ₹39Cr standalone, ₹47Cr consolidated. 9M FY26: highest-ever nine-month performance across revenue, EBITDA and PAT.
B35: ✅ Order Book at Record ₹2,226Cr | C35: Standalone order book ₹2,226Cr as of Dec 31, 2025 (2x annual revenue — strong visibility). Consolidated ₹2,566Cr. Q3 new orders: ₹476Cr. 9M order inflows: ₹852Cr. Q4 FY26 guidance: ₹550–600Cr of new orders (radar + EW systems). FY27 guidance: ₹1,500–1,600Cr.
B36: ✅ NEW: Demerger Approved | C36: Feb 27, 2026: Board gave in-principle approval for DEMERGER of Space, Meteorology & Hydrology businesses into a separate entity. This is a VALUE UNLOCK catalyst NOT in the original thesis. Focused entities, separate growth strategies, potential re-rating. Astra Space Technologies (wholly-owned sub, ex-CFO moved there) is the vehicle. This changes the calculus against tax-loss harvesting.
B37: Why Flat Revenue | C37: Revenue flat YoY (0.66%) because defence projects have long gestation — approvals, inspections, delivery schedules delayed by government processes, NOT business failure. High receivables and inventory are inherent to long-gestation contracts. Customer advances 20-30% mitigate exposure. This is a structural feature of the business, not deterioration.
B38: Strategic Catalysts | C38: MoU with BEL for indigenous design and production in key defence technologies — opens production order pipeline with India's largest defence PSU. Astra Rafael Comsys JV: $18.19M executed in Q3, $80M order book, ₹350Cr+ FY26 revenue, ₹400Cr+ FY27. PBT margins 10-12%. AMCA (fighter jet) program: Astra targeted as radar and EW suite supplier. Defence budget FY26: ₹7.85 lakh Cr (record).
B39: 📌 Revised Action Note | C39: VERDICT: THESIS DELAYED, NOT BROKEN. Do NOT tax-loss harvest. Q3 showed sequential recovery (margins, revenue). Order book at record. Demerger is a new unlocking catalyst. Key ask: need to see FY27 order inflows confirm ₹1,500Cr guidance (watch Q4 and Q1 FY27 results). If confirmed, this becomes a CORE position. Exit trigger stays: order book degrading below ₹1,500Cr, AMCA program removed.
B41: ⑤ IEX — ACCUMULATE | Build to 3–4% target weight. Zones: ₹115–120 (strong), ₹100–105 (aggressive add)
B42: ⚠️ APTEL Ruling — Feb 13 | C42: APTEL disposed IEX's appeal on Feb 13, 2026. CERC can now proceed with market coupling framework. HOWEVER: APTEL explicitly stated market coupling CANNOT be implemented until CERC notifies specific formal regulations. As of the ruling date, not even draft regulations had been issued. This means implementation is deferred — not dead.
B43: Coupling Timeline — Pushed | C43: JM Financial estimates coupling not before December 2027. CERC's own corrigendum reclassified its July 2025 'order' as 'directions' — reducing legal force. The regulatory pathway now requires: draft regulations → public comments → final regulations → implementation. Multi-step process means 18–24 month runway minimum.
B44: SEBI Insider Trading | C44: SEBI's Oct 2025 interim order found prima facie insider trading by CERC officials and connected entities trading in IEX options ahead of the July 23 coupling announcement. This taints the CERC order's credibility and is a legal anchor for IEX in any future challenge to final regulations. The regulator's credibility is damaged — helps IEX's long-term fight.
B45: ✅ Business Performing | C45: Feb 2026 volume: 12,550 MU — 30.4% YoY growth. Highest daily average volume ever. Business fundamentals are strong and accelerating. Electricity demand is structural. This is purely a regulatory overhang trade, not a deteriorating business story.
B46: Analyst Sentiment | C46: Bloomberg consensus: 4 Buy, 3 Hold, 6 Sell. Average 12-month target implies ~1% downside from current levels. Market is split. The Bear case: coupling erodes pricing power over 3–5 years. Bull case: coupling delayed to 2027+, volumes accelerate, overhang lifts. IEX has liberty to challenge final regulations when notified.
B47: 📌 Revised Action Note | C47: ACCUMULATING — position being increased. Market wrong on timing + magnitude. Coupling min 18–24 months away. Volume +30% YoY. Tainted CERC reduces enforcement appetite. Dividend yield ~2.5% while waiting. Target 3–4% weight. See ⚡ IEX Deep Dive for full thesis + triggers.
...

Sheet 🗺️ Portfolio Roadmap
B1: 🗺️ PORTFOLIO ROADMAP — 29 → 25 → 20 | Revised 7 Mar 2026 | Merges: Road to 20 + Consolidation Plan
B2: 27 active holdings (LIQUIDBEES removed, SGBs combined) · Wave 1 = execute this week · Wave 2 = gradual over 6-9 months
B4: 🚪 WAVE 1 EXITS — 29 → 26 | Execute this week | 3 confirmed exits
B5: STOCK | C5: WT | D5: P&L | E5: TAX | F5: PROCEEDS | G5: DEPLOY INTO | H5: RATIONALE
B6: ZYDUSLIFE | C6: 2.7% | D6: −3.4% | E6: STCL ~₹9,400 | F6: ~₹2.7L | G6: NH top-up | H6: No edge thesis. Exit on good quarter. Loss harvest useful offset.
B7: RAINBOW | C7: 2.8% | D7: −5% | E7: LTCL harvest (zero LTCG) | F7: ~₹2.85L | G7: NH top-up | H7: Duplicate vs NH. Occupancy 47% vs target 55-60%. NH stronger compounder.
B8: LT | C8: 4.2% | D8: +7% | E8: STCG ~₹2,100 (minimal) | F8: ~₹4.3L | G8: MEDIASSIST primary | H8: Underwhelming return. KIRLOSENG covers capex. No LT friction. Deploy to conviction.
B10: ✂️ WAVE 1 TRIMS — Concurrent with exits
B11: STOCK | C11: CUR WT | D11: TARGET WT | E11: SHARES TO SELL | F11: PROCEEDS | G11: TAX NOTE | H11: REDEPLOY INTO
B12: UJJIVANSFB | C12: 5.4% | D12: 2.5–3% | E12: ~5,000 shares | F12: ~₹2.7L | G12: STCG on +30% ~₹37,500 | H12: UTKARSHBNK primary · CREDITACC on dips
B13: COALINDIA | C13: 5.2% | D13: 2.5–3% | E13: ~420 shares | F13: ~₹1.8L | G13: STCG on +12% ~₹6,600 | H13: NH top-up
B15: ⚡ EXECUTION SEQUENCE — Ordered by urgency
B16: STEP | C16: TIMING | D16: ACTION | E16: STOCK | F16: CAPITAL IMPACT | G16: NOTE
B17: 1 | C17: NOW | D17: ACCUMULATE | E17: IEX | F17: ₹115–120 zone | G17: Build to 3-4%. See ⚡ IEX Deep Dive
B18: 2 | C18: BEFORE MAR 20 | D18: MONITOR — do NOT add yet | E18: MEDIASSIST | F18: Watch IRDAI renewal | G18: Binary — confirm licence renewal Mar 20 before adding
B19: 3 | C19: THIS WEEK | D19: EXIT all 300 shares | E19: ZYDUSLIFE | F19: ~₹2.7L freed | G19: STCL ~₹9,400 — useful offset
B20: 4 | C20: THIS WEEK | D20: EXIT all 235 shares | E20: RAINBOW | F20: ~₹2.85L freed | G20: LTCL + STCL harvest. Zero LTCG
B21: 5 | C21: THIS WEEK | D21: TRIM ~420 shares | E21: COALINDIA | F21: ~₹1.8L freed | G21: STCG ~₹6,600 on +12%
B22: 6 | C22: THIS WEEK | D22: TRIM ~5,000 shares | E22: UJJIVANSFB | F22: ~₹2.7L freed | G22: STCG ~₹37,500 on +30%
B23: 7 | C23: THIS WEEK / AFTER IRDAI | D23: EXIT all 110 shares (keep 20 tracker if wanted) | E23: LT | F23: ~₹4.3L freed | G23: STCG ~₹2,100 — minimal
B24: 8 | C24: AFTER EXITS | D24: ADD ~100–120 shares | E24: NH | F24: Deploy RAINBOW + COALINDIA ~₹5L | G24: Fresh STCG basis
B25: 9 | C25: AFTER IRDAI MAR 20 | D25: ADD tranches | E25: MEDIASSIST | F25: Deploy LT proceeds ~₹3–4L | G25: Fresh basis at ~₹340
B26: 10 | C26: EACH CLEAN QUARTER | D26: ADD tranches | E26: UTKARSHBNK | F26: Deploy UJJIVANSFB proceeds ~₹2L+ | G26: Fresh basis at ~₹13
B27: 11 | C27: ON DIPS | D27: ADD opportunistically | E27: CREDITACC | F27: Residual trim proceeds | G27: 275 LT already held
B28: 12 | C28: ON DIPS | D28: MODEST ADD ~10–15 shares | E28: ECLERX | F28: ~₹0.3–0.5L | G28: Promoter ₹4,800 signal anchor
B30: 💰 CAPITAL REDEPLOYMENT — ~₹11–12L freed → where it goes
B31: TARGET | C31: SECTOR | D31: CAPITAL FROM | E31: AMOUNT | F31: NEW WT | G31: NOTE
B32: NH | C32: HEALTHCARE | D32: RAINBOW + partial COALINDIA | E32: ~₹4–5L | F32: 6–7% | G32: Cayman inflecting. Cheapest hospital chain. 200 LT held, add 100-120 more.
B33: UTKARSHBNK | C33: MICROFINANCE | D33: UJJIVANSFB trim (primary) | E33: ~₹2L+ | F33: 4–5% | G33: DPD 87% cleared. Smart money rights ₹14. Add each clean quarterly print.
B34: MEDIASSIST | C34: HEALTHCARE INFRA | D34: LT exit + partial ZYDUS | E34: ~₹3–4L | F34: 5–6% | G34: Post IRDAI confirmation Mar 20. MIT anchor ₹535 vs CMP ₹340.
B35: CREDITACC | C35: MICROFINANCE | D35: UJJIVANSFB trim (secondary — dips only) | E35: ~₹0.7L | F35: 4.5–5% | G35: 275 LT held. Quality MFI anchor. Opportunistic only.
B37: 🎯 TARGET PORTFOLIO — 25 stocks now → 20 stocks (6-9 months)
B38: # | C38: STOCK | D38: SECTOR | E38: ACTION | F38: TARGET WT | G38: CONVICTION | H38: THESIS IN ONE LINE
B39: 1 | C39: GOLDIETF-E | D39: ETF / GOLD | E39: HOLD FULL | F39: 10–11% | G39: ⭐ STRUCTURAL | H39: Central bank demand + dollar re-rating. No trim.
B40: 2 | C40: BAJFINANCE | D40: CONSUMER LENDING | E40: HOLD | F40: 6–7% | G40: ⭐ CORE | H40: Consumer lending market leader. 43% gain. Running.
B41: 3 | C41: NH | D41: HEALTHCARE | E41: SIZE UP → HOLD | F41: 6–7% | G41: ⭐ HIGH CONV. | H41: Cayman inflecting. Cheapest hospital chain. Asset-light compounder.
B42: 4 | C42: MEDIASSIST | D42: HEALTHCARE INFRA | E42: ACCUMULATE | F42: 5–7% | G42: ⭐ HIGH CONV. | H42: TPA market leader. MIT anchor ₹535. Platform moat.
B43: 5 | C43: ICICIBANK | D43: BANKING | E43: HOLD | F43: 5–6% | G43: ⭐ CORE | H43: Best-in-class private bank. Consistent compounder.
B44: 6 | C44: HOMEFIRST | D44: HOUSING FINANCE | E44: HOLD | F44: 4–5% | G44: ⭐ CORE | H44: 441 LT shares. Affordable housing cycle.
B45: 7 | C45: CARYSIL | D45: FMCG / EXPORT | E45: HOLD | F45: 4–5% | G45: HIGH | H45: Niche quartz sink exporter. 425 LT. Global cycle play.
...

Sheet ⚠️ Risk Flags
B1: RISK & CONCENTRATION FLAGS
B3: Symbol | C3: Sector | D3: Flag Type | E3: Detail | F3: Severity
B4: GOLDIETF-E | C4: ETF | D4: CONCENTRATION | E4: Single stock 10.9% of portfolio (>10%) | F4: HIGH
B5: GOLDIETF-E | C5: ETF | D5: LARGE GAIN — REVIEW | E5: Gain +63.7% — LTCG & rebalancing? | F5: NOTE
B6: CHAMBLFERT | C6: FERTILIZERS | D6: MODERATE LOSS | E6: Unrealised loss -8.7% | F6: MEDIUM
B7: UTKARSHBNK | C7: MICROFINANCE | D7: MODERATE LOSS | E7: Unrealised loss -6.4% | F7: MEDIUM
B8: CAMS | C8: MARKET INFRASTRUCTURE | D8: MODERATE LOSS | E8: Unrealised loss -10.7% | F8: MEDIUM
B9: MEDIASSIST | C9: SOFTWARE SERVICES | D9: DEEP LOSS | E9: Unrealised loss -18.2% — review thesis | F9: HIGH
B10: IEX | C10: ENERGY | D10: DEEP LOSS — THESIS INTACT | E10: Unrealised loss -18.2% — thesis confirmed, accumulating. Coupling 18–24 months away. Volume +30% YoY. Tainted CERC = reduced enforcement risk. | F10: MEDIUM
B11: PERSISTENT | C11: SOFTWARE SERVICES | D11: MODERATE LOSS | E11: Unrealised loss -8.4% | F11: MEDIUM
B12: PORTFOLIO | C12: FINANCE (ALL SUBS) | D12: AGGREGATE FINANCE EXPOSURE | E12: All finance sub-sectors combined = 42.3% of portfolio | F12: NOTE
B15: Analysis as of 5 Mar 2026 | 9 flags | 29 holdings | BAJFINANCE avg corrected to ₹660

Sheet 🎯 Scenario Analysis
B1: SCENARIO ANALYSIS
B2: Uniform market move on CMP. LTCG at 12.5% on LT gains >₹1.25L exemption. Estimates only.
B4: Scenario | C4: Move | D4: Portfolio Value (₹) | E4: Total P&L (₹) | F4: Return on Cost | G4: Change vs Today (₹) | H4: Est. LTCG Tax (₹) | I4: Post-Tax Value (₹)
B5: Bear (−20%) | C5: -20% | D5: {=SUM(H14:H42)} -> 8095859.1 | E5: {=D5-'📊 Portfolio Brief'!$G$40} -> -694146.51 | F5: {=E5/'📊 Portfolio Brief'!$G$40} -> -0.078969973 | G5: {=D5-D7} -> -2023964.8 | H5: 0 | I5: 8095903.1
B6: Mild Bear (−10%) | C6: -10% | D6: {=SUM(I14:I42)} -> 9107841.5 | E6: {=D6-'📊 Portfolio Brief'!$G$40} -> 317835.88 | F6: {=E6/'📊 Portfolio Brief'!$G$40} -> 0.03615878 | G6: {=D6-D7} -> -1011982.4 | H6: 12945.887 | I6: 9094945.1
B7: Base (0% — Today) | C7: +0% | D7: {=SUM(J14:J42)} -> 10119824 | E7: {=D7-'📊 Portfolio Brief'!$G$40} -> 1329818.3 | F7: {=E7/'📊 Portfolio Brief'!$G$40} -> 0.15128753 | G7: {=D7-D7} -> 0 | H7: 45361.464 | I7: 10074517
B8: Bull (+15%) | C8: +15% | D8: {=SUM(K14:K42)} -> 11637797 | E8: {=D8-'📊 Portfolio Brief'!$G$40} -> 2847791.8 | F8: {=E8/'📊 Portfolio Brief'!$G$40} -> 0.32398066 | G8: {=D8-D7} -> 1517973.6 | H8: 100286.63 | I8: 11537574
B9: Strong Bull (+30%) | C9: +30% | D9: {=SUM(L14:L42)} -> 13155771 | E9: {=D9-'📊 Portfolio Brief'!$G$40} -> 4365765.4 | F9: {=E9/'📊 Portfolio Brief'!$G$40} -> 0.49667379 | G9: {=D9-D7} -> 3035947.2 | H9: 160097.54 | I9: 12995745
B12: STOCK-LEVEL SCENARIO VALUES
B13: Symbol | C13: Sector | D13: Qty | E13: Avg Cost | F13: CMP | G13: Today Val | H13: Bear −20% | I13: Mild −10% | J13: Base 0% | K13: Bull +15% | L13: S.Bull +30% | M13: Bear P&L | N13: Base P&L | O13: Bull P&L | P13: S.Bull P&L
B14: GOLDIETF-E | C14: ETF | D14: 8000 | E14: 84.4748 | F14: {=_xlfn.IFERROR(VLOOKUP(B14,'📥 Price Hub'!$B$5:$H$34,7,0),0)} -> 138.3 | G14: {=D14*F14} -> 1106400 | H14: {=G14*0.8} -> 885120 | I14: {=G14*0.9} -> 995760 | J14: {=G14} -> 1106400 | K14: {=G14*1.15} -> 1272360 | L14: {=G14*1.3} -> 1438320 | M14: {=H14-E14*D14} -> 209321.6 | N14: {=J14-E14*D14} -> 430601.6 | O14: {=K14-E14*D14} -> 596561.6 | P14: {=L14-E14*D14} -> 762521.6
B15: BAJFINANCE | C15: CONSUMER LENDING | D15: 750 | E15: 660 | F15: {=_xlfn.IFERROR(VLOOKUP(B15,'📥 Price Hub'!$B$5:$H$34,7,0),0)} -> 945.1 | G15: {=D15*F15} -> 708825 | H15: {=G15*0.8} -> 567060 | I15: {=G15*0.9} -> 637942.5 | J15: {=G15} -> 708825 | K15: {=G15*1.15} -> 815148.75 | L15: {=G15*1.3} -> 921472.5 | M15: {=H15-E15*D15} -> 72060 | N15: {=J15-E15*D15} -> 213825 | O15: {=K15-E15*D15} -> 320148.75 | P15: {=L15-E15*D15} -> 426472.5
B16: UJJIVANSFB | C16: MICROFINANCE | D16: 10074 | E16: 41.8047 | F16: {=_xlfn.IFERROR(VLOOKUP(B16,'📥 Price Hub'!$B$5:$H$34,7,0),0)} -> 54.27 | G16: {=D16*F16} -> 546715.98 | H16: {=G16*0.8} -> 437372.78 | I16: {=G16*0.9} -> 492044.38 | J16: {=G16} -> 546715.98 | K16: {=G16*1.15} -> 628723.38 | L16: {=G16*1.3} -> 710730.77 | M16: {=H16-E16*D16} -> 16232.236 | N16: {=J16-E16*D16} -> 125575.43 | O16: {=K16-E16*D16} -> 207582.83 | P16: {=L16-E16*D16} -> 289590.23
B17: COALINDIA | C17: METALS | D17: 1200 | E17: 388.9194 | F17: {=_xlfn.IFERROR(VLOOKUP(B17,'📥 Price Hub'!$B$5:$H$34,7,0),0)} -> 435.15 | G17: {=D17*F17} -> 522180 | H17: {=G17*0.8} -> 417744 | I17: {=G17*0.9} -> 469962 | J17: {=G17} -> 522180 | K17: {=G17*1.15} -> 600507 | L17: {=G17*1.3} -> 678834 | M17: {=H17-E17*D17} -> -48959.28 | N17: {=J17-E17*D17} -> 55476.72 | O17: {=K17-E17*D17} -> 133803.72 | P17: {=L17-E17*D17} -> 212130.72
B18: ICICIBANK | C18: BANKING | D18: 375 | E18: 1154.2536 | F18: {=_xlfn.IFERROR(VLOOKUP(B18,'📥 Price Hub'!$B$5:$H$34,7,0),0)} -> 1365.4 | G18: {=D18*F18} -> 512025 | H18: {=G18*0.8} -> 409620 | I18: {=G18*0.9} -> 460822.5 | J18: {=G18} -> 512025 | K18: {=G18*1.15} -> 588828.75 | L18: {=G18*1.3} -> 665632.5 | M18: {=H18-E18*D18} -> -23225.1 | N18: {=J18-E18*D18} -> 79179.9 | O18: {=K18-E18*D18} -> 155983.65 | P18: {=L18-E18*D18} -> 232787.4
B19: HOMEFIRST | C19: HOUSING FINANCE | D19: 441 | E19: 934.6512 | F19: {=_xlfn.IFERROR(VLOOKUP(B19,'📥 Price Hub'!$B$5:$H$34,7,0),0)} -> 1074.4 | G19: {=D19*F19} -> 473810.4 | H19: {=G19*0.8} -> 379048.32 | I19: {=G19*0.9} -> 426429.36 | J19: {=G19} -> 473810.4 | K19: {=G19*1.15} -> 544881.96 | L19: {=G19*1.3} -> 615953.52 | M19: {=H19-E19*D19} -> -33132.859 | N19: {=J19-E19*D19} -> 61629.221 | O19: {=K19-E19*D19} -> 132700.78 | P19: {=L19-E19*D19} -> 203772.34
B20: CARYSIL | C20: FMCG | D20: 550 | E20: 743.8698 | F20: {=_xlfn.IFERROR(VLOOKUP(B20,'📥 Price Hub'!$B$5:$H$34,7,0),0)} -> 859.1 | G20: {=D20*F20} -> 472505 | H20: {=G20*0.8} -> 378004 | I20: {=G20*0.9} -> 425254.5 | J20: {=G20} -> 472505 | K20: {=G20*1.15} -> 543380.75 | L20: {=G20*1.3} -> 614256.5 | M20: {=H20-E20*D20} -> -31124.39 | N20: {=J20-E20*D20} -> 63376.61 | O20: {=K20-E20*D20} -> 134252.36 | P20: {=L20-E20*D20} -> 205128.11
B21: BANKBARODA | C21: BANKING | D21: 1500 | E21: 241.5191 | F21: {=_xlfn.IFERROR(VLOOKUP(B21,'📥 Price Hub'!$B$5:$H$34,7,0),0)} -> 299.3 | G21: {=D21*F21} -> 448950 | H21: {=G21*0.8} -> 359160 | I21: {=G21*0.9} -> 404055 | J21: {=G21} -> 448950 | K21: {=G21*1.15} -> 516292.5 | L21: {=G21*1.3} -> 583635 | M21: {=H21-E21*D21} -> -3118.65 | N21: {=J21-E21*D21} -> 86671.35 | O21: {=K21-E21*D21} -> 154013.85 | P21: {=L21-E21*D21} -> 221356.35
B22: CREDITACC | C22: MICROFINANCE | D22: 350 | E22: 961.5244 | F22: {=_xlfn.IFERROR(VLOOKUP(B22,'📥 Price Hub'!$B$5:$H$34,7,0),0)} -> 1225.8 | G22: {=D22*F22} -> 429030 | H22: {=G22*0.8} -> 343224 | I22: {=G22*0.9} -> 386127 | J22: {=G22} -> 429030 | K22: {=G22*1.15} -> 493384.5 | L22: {=G22*1.3} -> 557739 | M22: {=H22-E22*D22} -> 6690.46 | N22: {=J22-E22*D22} -> 92496.46 | O22: {=K22-E22*D22} -> 156850.96 | P22: {=L22-E22*D22} -> 221205.46
B23: LT | C23: ENGINEERING & CAPITAL GOODS | D23: 110 | E23: 3614.1977 | F23: {=_xlfn.IFERROR(VLOOKUP(B23,'📥 Price Hub'!$B$5:$H$34,7,0),0)} -> 3882.6 | G23: {=D23*F23} -> 427086 | H23: {=G23*0.8} -> 341668.8 | I23: {=G23*0.9} -> 384377.4 | J23: {=G23} -> 427086 | K23: {=G23*1.15} -> 491148.9 | L23: {=G23*1.3} -> 555211.8 | M23: {=H23-E23*D23} -> -55892.947 | N23: {=J23-E23*D23} -> 29524.253 | O23: {=K23-E23*D23} -> 93587.153 | P23: {=L23-E23*D23} -> 157650.05
B24: NH | C24: HEALTHCARE | D24: 240 | E24: 1336.4402 | F24: {=_xlfn.IFERROR(VLOOKUP(B24,'📥 Price Hub'!$B$5:$H$34,7,0),0)} -> 1744 | G24: {=D24*F24} -> 418560 | H24: {=G24*0.8} -> 334848 | I24: {=G24*0.9} -> 376704 | J24: {=G24} -> 418560 | K24: {=G24*1.15} -> 481344 | L24: {=G24*1.3} -> 544128 | M24: {=H24-E24*D24} -> 14102.352 | N24: {=J24-E24*D24} -> 97814.352 | O24: {=K24-E24*D24} -> 160598.35 | P24: {=L24-E24*D24} -> 223382.35
B25: HDFCBANK | C25: BANKING | D25: 450 | E25: 626.6593 | F25: {=_xlfn.IFERROR(VLOOKUP(B25,'📥 Price Hub'!$B$5:$H$34,7,0),0)} -> 868.65 | G25: {=D25*F25} -> 390892.5 | H25: {=G25*0.8} -> 312714 | I25: {=G25*0.9} -> 351803.25 | J25: {=G25} -> 390892.5 | K25: {=G25*1.15} -> 449526.38 | L25: {=G25*1.3} -> 508160.25 | M25: {=H25-E25*D25} -> 30717.315 | N25: {=J25-E25*D25} -> 108895.82 | O25: {=K25-E25*D25} -> 167529.69 | P25: {=L25-E25*D25} -> 226163.57
... B40: SGB-COMBINED | C40: SOVEREIGN GOLD BOND | D40: 6 | E40: 16262.96 | F40: {=_xlfn.IFERROR(VLOOKUP(B40,'📥 Price Hub'!$B$5:$H$34,7,0),0)} -> 16392.83 | G40: {=D40*F40} -> 98356.98 | H40: {=G40*0.8} -> 78685.584 | I40: {=G40*0.9} -> 88521.282 | J40: {=G40} -> 98356.98 | K40: {=G40*1.15} -> 113110.53 | L40: {=G40*1.3} -> 127864.07 | M40: {=H40-E40*D40} -> -18892.176 | N40: {=J40-E40*D40} -> 779.22 | O40: {=K40-E40*D40} -> 15532.767 | P40: {=L40-E40*D40} -> 30286.314
D41: 0
D42: 0
B45: * LTCG at 12.5% on LT gains >₹1.25L exemption. Estimates only — consult tax advisor.

Sheet 🏭 Sector Analysis
B1: SECTOR BREAKDOWN — 15 SUB-SECTORS
B2: Finance split: Banking · Consumer Lending · Housing Finance · Microfinance · Market Infrastructure
B4: Sector | C4: Holdings | D4: Invested (₹) | E4: Mkt Value (₹) | F4: P&L (₹) | G4: Return % | H4: Portfolio Wt
B5: · BANKING | C5: {=COUNTIF('📊 Portfolio Brief'!$C$11:$C$39,"BANKING")} -> 3 | D5: {=SUMIF('📊 Portfolio Brief'!$C$11:$C$39,"BANKING",'📊 Portfolio Brief'!$G$11:$G$39)} -> 1077120.4 | E5: {=SUMIF('📊 Portfolio Brief'!$C$11:$C$39,"BANKING",'📊 Portfolio Brief'!$H$11:$H$39)} -> 1351867.5 | F5: {=E5-D5} -> 274747.07 | G5: {=IF(D5=0,0,F5/D5)} -> 0.25507553 | H5: {=IF(SUM(E5:E19)=0,0,E5/SUM(E5:E19))} -> 0.13358607
B6: · MICROFINANCE | C6: {=COUNTIF('📊 Portfolio Brief'!$C$11:$C$39,"MICROFINANCE")} -> 3 | D6: {=SUMIF('📊 Portfolio Brief'!$C$11:$C$39,"MICROFINANCE",'📊 Portfolio Brief'!$G$11:$G$39)} -> 1066485.9 | E6: {=SUMIF('📊 Portfolio Brief'!$C$11:$C$39,"MICROFINANCE",'📊 Portfolio Brief'!$H$11:$H$39)} -> 1264826 | F6: {=E6-D6} -> 198340.09 | G6: {=IF(D6=0,0,F6/D6)} -> 0.18597536 | H6: {=IF(SUM(E5:E19)=0,0,E6/SUM(E5:E19))} -> 0.12498498
B7: ETF | C7: {=COUNTIF('📊 Portfolio Brief'!$C$11:$C$39,"ETF")} -> 2 | D7: {=SUMIF('📊 Portfolio Brief'!$C$11:$C$39,"ETF",'📊 Portfolio Brief'!$G$11:$G$39)} -> 789934.4 | E7: {=SUMIF('📊 Portfolio Brief'!$C$11:$C$39,"ETF",'📊 Portfolio Brief'!$H$11:$H$39)} -> 1241900 | F7: {=E7-D7} -> 451965.6 | G7: {=IF(D7=0,0,F7/D7)} -> 0.57215587 | H7: {=IF(SUM(E5:E19)=0,0,E7/SUM(E5:E19))} -> 0.12271953
B8: HEALTHCARE | C8: {=COUNTIF('📊 Portfolio Brief'!$C$11:$C$39,"HEALTHCARE")} -> 3 | D8: {=SUMIF('📊 Portfolio Brief'!$C$11:$C$39,"HEALTHCARE",'📊 Portfolio Brief'!$G$11:$G$39)} -> 899577.31 | E8: {=SUMIF('📊 Portfolio Brief'!$C$11:$C$39,"HEALTHCARE",'📊 Portfolio Brief'!$H$11:$H$39)} -> 973084.5 | F8: {=E8-D8} -> 73507.189 | G8: {=IF(D8=0,0,F8/D8)} -> 0.081713031 | H8: {=IF(SUM(E5:E19)=0,0,E8/SUM(E5:E19))} -> 0.096156268
B9: FMCG | C9: {=COUNTIF('📊 Portfolio Brief'!$C$11:$C$39,"FMCG")} -> 2 | D9: {=SUMIF('📊 Portfolio Brief'!$C$11:$C$39,"FMCG",'📊 Portfolio Brief'!$G$11:$G$39)} -> 759780.75 | E9: {=SUMIF('📊 Portfolio Brief'!$C$11:$C$39,"FMCG",'📊 Portfolio Brief'!$H$11:$H$39)} -> 814065 | F9: {=E9-D9} -> 54284.25 | G9: {=IF(D9=0,0,F9/D9)} -> 0.071447256 | H9: {=IF(SUM(E5:E19)=0,0,E9/SUM(E5:E19))} -> 0.080442606
B10: · CONSUMER LENDING | C10: {=COUNTIF('📊 Portfolio Brief'!$C$11:$C$39,"CONSUMER LENDING")} -> 1 | D10: {=SUMIF('📊 Portfolio Brief'!$C$11:$C$39,"CONSUMER LENDING",'📊 Portfolio Brief'!$G$11:$G$39)} -> 495000 | E10: {=SUMIF('📊 Portfolio Brief'!$C$11:$C$39,"CONSUMER LENDING",'📊 Portfolio Brief'!$H$11:$H$39)} -> 708825 | F10: {=E10-D10} -> 213825 | G10: {=IF(D10=0,0,F10/D10)} -> 0.4319697 | H10: {=IF(SUM(E5:E19)=0,0,E10/SUM(E5:E19))} -> 0.070043215
B11: ENGINEERING & CAPITAL GOODS | C11: {=COUNTIF('📊 Portfolio Brief'!$C$11:$C$39,"ENGINEERING & CAPITAL GOODS")} -> 2 | D11: {=SUMIF('📊 Portfolio Brief'!$C$11:$C$39,"ENGINEERING & CAPITAL GOODS",'📊 Portfolio Brief'!$G$11:$G$39)} -> 570392.04 | E11: {=SUMIF('📊 Portfolio Brief'!$C$11:$C$39,"ENGINEERING & CAPITAL GOODS",'📊 Portfolio Brief'!$H$11:$H$39)} -> 682056 | F11: {=E11-D11} -> 111663.96 | G11: {=IF(D11=0,0,F11/D11)} -> 0.19576704 | H11: {=IF(SUM(E5:E19)=0,0,E11/SUM(E5:E19))} -> 0.067398011
B12: · HOUSING FINANCE | C12: {=COUNTIF('📊 Portfolio Brief'!$C$11:$C$39,"HOUSING FINANCE")} -> 2 | D12: {=SUMIF('📊 Portfolio Brief'!$C$11:$C$39,"HOUSING FINANCE",'📊 Portfolio Brief'!$G$11:$G$39)} -> 587559.04 | E12: {=SUMIF('📊 Portfolio Brief'!$C$11:$C$39,"HOUSING FINANCE",'📊 Portfolio Brief'!$H$11:$H$39)} -> 675936.65 | F12: {=E12-D12} -> 88377.608 | G12: {=IF(D12=0,0,F12/D12)} -> 0.15041486 | H12: {=IF(SUM(E5:E19)=0,0,E12/SUM(E5:E19))} -> 0.066793322
B13: SOFTWARE SERVICES | C13: {=COUNTIF('📊 Portfolio Brief'!$C$11:$C$39,"SOFTWARE SERVICES")} -> 3 | D13: {=SUMIF('📊 Portfolio Brief'!$C$11:$C$39,"SOFTWARE SERVICES",'📊 Portfolio Brief'!$G$11:$G$39)} -> 629447.28 | E13: {=SUMIF('📊 Portfolio Brief'!$C$11:$C$39,"SOFTWARE SERVICES",'📊 Portfolio Brief'!$H$11:$H$39)} -> 555600 | F13: {=E13-D13} -> -73847.28 | G13: {=IF(D13=0,0,F13/D13)} -> -0.11732083 | H13: {=IF(SUM(E5:E19)=0,0,E13/SUM(E5:E19))} -> 0.054902141
B14: METALS | C14: {=COUNTIF('📊 Portfolio Brief'!$C$11:$C$39,"METALS")} -> 1 | D14: {=SUMIF('📊 Portfolio Brief'!$C$11:$C$39,"METALS",'📊 Portfolio Brief'!$G$11:$G$39)} -> 466703.28 | E14: {=SUMIF('📊 Portfolio Brief'!$C$11:$C$39,"METALS",'📊 Portfolio Brief'!$H$11:$H$39)} -> 522180 | F14: {=E14-D14} -> 55476.72 | G14: {=IF(D14=0,0,F14/D14)} -> 0.11886936 | H14: {=IF(SUM(E5:E19)=0,0,E14/SUM(E5:E19))} -> 0.051599712
B15: DEFENCE | C15: {=COUNTIF('📊 Portfolio Brief'!$C$11:$C$39,"DEFENCE")} -> 1 | D15: {=SUMIF('📊 Portfolio Brief'!$C$11:$C$39,"DEFENCE",'📊 Portfolio Brief'!$G$11:$G$39)} -> 377433.11 | E15: {=SUMIF('📊 Portfolio Brief'!$C$11:$C$39,"DEFENCE",'📊 Portfolio Brief'!$H$11:$H$39)} -> 373331.25 | F15: {=E15-D15} -> -4101.8625 | G15: {=IF(D15=0,0,F15/D15)} -> -0.010867787 | H15: {=IF(SUM(E5:E19)=0,0,E15/SUM(E5:E19))} -> 0.036891082
B16: FERTILIZERS | C16: {=COUNTIF('📊 Portfolio Brief'!$C$11:$C$39,"FERTILIZERS")} -> 1 | D16: {=SUMIF('📊 Portfolio Brief'!$C$11:$C$39,"FERTILIZERS",'📊 Portfolio Brief'!$G$11:$G$39)} -> 401518.66 | E16: {=SUMIF('📊 Portfolio Brief'!$C$11:$C$39,"FERTILIZERS",'📊 Portfolio Brief'!$H$11:$H$39)} -> 366605 | F16: {=E16-D16} -> -34913.665 | G16: {=IF(D16=0,0,F16/D16)} -> -0.086954027 | H16: {=IF(SUM(E5:E19)=0,0,E16/SUM(E5:E19))} -> 0.036226421
B17: · MARKET INFRASTRUCTURE | C17: {=COUNTIF('📊 Portfolio Brief'!$C$11:$C$39,"MARKET INFRASTRUCTURE")} -> 1 | D17: {=SUMIF('📊 Portfolio Brief'!$C$11:$C$39,"MARKET INFRASTRUCTURE",'📊 Portfolio Brief'!$G$11:$G$39)} -> 317821.01 | E17: {=SUMIF('📊 Portfolio Brief'!$C$11:$C$39,"MARKET INFRASTRUCTURE",'📊 Portfolio Brief'!$H$11:$H$39)} -> 283657.5 | F17: {=E17-D17} -> -34163.505 | G17: {=IF(D17=0,0,F17/D17)} -> -0.10749291 | H17: {=IF(SUM(E5:E19)=0,0,E17/SUM(E5:E19))} -> 0.028029885
B18: ENERGY | C18: {=COUNTIF('📊 Portfolio Brief'!$C$11:$C$39,"ENERGY")} -> 1 | D18: {=SUMIF('📊 Portfolio Brief'!$C$11:$C$39,"ENERGY",'📊 Portfolio Brief'!$G$11:$G$39)} -> 253654.62 | E18: {=SUMIF('📊 Portfolio Brief'!$C$11:$C$39,"ENERGY",'📊 Portfolio Brief'!$H$11:$H$39)} -> 207532.5 | F18: {=E18-D18} -> -46122.125 | G18: {=IF(D18=0,0,F18/D18)} -> -0.18183041 | H18: {=IF(SUM(E5:E19)=0,0,E18/SUM(E5:E19))} -> 0.020507521
B19: SOVEREIGN GOLD BOND | C19: {=COUNTIF('📊 Portfolio Brief'!$C$11:$C$39,"SOVEREIGN GOLD BOND")} -> 1 | D19: {=SUMIF('📊 Portfolio Brief'!$C$11:$C$39,"SOVEREIGN GOLD BOND",'📊 Portfolio Brief'!$G$11:$G$39)} -> 97577.76 | E19: {=SUMIF('📊 Portfolio Brief'!$C$11:$C$39,"SOVEREIGN GOLD BOND",'📊 Portfolio Brief'!$H$11:$H$39)} -> 98356.98 | F19: {=E19-D19} -> 779.22 | G19: {=IF(D19=0,0,F19/D19)} -> 0.0079856312 | H19: {=IF(SUM(E5:E19)=0,0,E19/SUM(E5:E19))} -> 0.0097192383
B21: TOTAL FINANCE EXPOSURE | C21: {=SUM(C5,C6,C10,C12,C17)} -> 10 | D21: {=SUM(D5,D6,D10,D12,D17)} -> 3543986.4 | E21: {=SUM(E5,E6,E10,E12,E17)} -> 4285112.6 | F21: {=E21-D21} -> 741126.26 | G21: {=IF(D21=0,0,F21/D21)} -> 0.20912221 | H21: {=IF(SUM(E5:E19)=0,0,E21/SUM(E5:E19))} -> 0.42343747
B23: GRAND TOTAL | C23: 29 | D23: {=SUM(D5:D22)} -> 12333992 | E23: {=SUM(E5:E22)} -> 14404936 | F23: {=E23-D23} -> 2070944.5 | G23: {=F23/D23} -> 0.16790545 | H23: 1

Sheet 💻 IT Sector Analysis
B2: 💻 IT SECTOR — Sell-off Analysis & Portfolio Positioning | 6 March 2026
B3: Is the broad-based selling structural or panic? Where does the portfolio sit? What is the right action?
B6: CONFIRMED: Broad-based FII + Retail selling | C6: Nifty IT fell ~20% in February 2026 — worst monthly fall since March 2020. ₹5.7 lakh crore in market cap erased in under two weeks. FPIs pulled ₹10,956Cr from IT in just the first half of February. Total FII IT outflow in 2025: ₹74,698Cr — 8 months of sustained, deliberate sector deweight. FII holdings in IT at a 4-year low. Infosys FII stake: 30.68%, HCL Tech: 16.2%. Retail also selling: domestic MF IT allocation at ~8% vs ~9% index weight — even MFs are underweight. DII buying has NOT absorbed the FII selling. This is both institutional AND retail — broad-based confirmed.
B7: THE TRIGGER — 'Anthropic Shock' | C7: Market participants are using the term 'Anthropic shock' for the Feb 2026 sell-off trigger: Anthropic enterprise AI workplace tools + Palantir releases intensified fears that generative AI automates Application Development & Maintenance — the backbone of Indian IT billing. Infosys ADR fell 10% in a single US session, cascading to NSE. The fear is real for the WRONG companies. T&M billing models with 60%+ entry-level headcount (TCS, Infosys, Wipro, Tech Mahindra) ARE structurally at risk. AI does substitute junior code-level work billed per hour. Motilal Oswal estimates 9–12% of IT services revenue at risk over 3–4 years for these models.
